Workbook

Sheet Test Case-lər
A1: ID | B1: Modul | C1: Başlıq | D1: Ön şərt | E1: Addımlar | F1: Test məlumatı | G1: Gözlənilən nəticə | H1: Prioritet | I1: Tip | J1: Avtomatlaşdırma | K1: Status | L1: Qeyd
A2: UI-LNG-001 | B2: Dil | C2: Defolt dil: kök URL (/) açılışı | D2: Brauzer açıqdır | E2: 1. Brauzerdə https://www.bankofbaku.com açın | G2: Həmişə İngilis dilində açılır (məlum davranış). Dil seçimi menyuda EN aktiv göstərilir | H2: Yüksək | I2: Pozitiv | J2: Yox | K2: Keçdi | L2: Real Chrome-da Accept-Language səbəbindən /az-a yönləndirdi; Selenium Chrome-da kök URL EN açılır – davranış brauzer dilindən asılıdır
A3: UI-LNG-002 | B3: Dil | C3: Birbaşa /az linki Azərbaycan dilində açılır | D3: - | E3: 1. https://www.bankofbaku.com/az açın | G3: Məzmun Azərbaycan dilindədir; menyuda AZ aktivdir; html lang="az" | H3: Yüksək | I3: Pozitiv | J3: Bəli | K3: Keçdi | L3: Avtomatik test (UI-LNG-002) və əl ilə təsdiqləndi
A4: UI-LNG-003 | B4: Dil | C4: Birbaşa /en linki | D4: Brauzer açıqdır | E4: 1. https://www.bankofbaku.com/en açın | G4: Məzmun İngilis dilindədir; html lang="en" | H4: Orta | I4: Pozitiv | J4: Bəli | K4: Uğursuz | L4: /en məzmunu İngilis dilindədir, lakin html lang="az" və başlıq Azərbaycan dilində qalır (BUG-008, BUG-009) | Avtomatik: language.spec
A5: UI-LNG-004 | B5: Dil | C5: Birbaşa /ru linki | D5: Brauzer açıqdır | E5: 1. https://www.bankofbaku.com/ru açın | G5: Məzmun Rus dilindədir; html lang="ru" | H5: Orta | I5: Pozitiv | J5: Yox | K5: Uğursuz | L5: /ru məzmunu Rus dilindədir, lakin html lang="az" və başlıq Azərbaycan dilində qalır (BUG-008, BUG-009)
A6: UI-LNG-005 | B6: Dil | C6: Dil menyusundan AZ-ya keçid | D6: Brauzer açıqdır | E6: 1. Kök URL açın (EN) 2. Dil menyusundan AZ seçin | G6: URL /az olur, bütün mətn tərcümə olunur, səhifə yenilənmədən və ya düzgün yüklənir | H6: Yüksək | I6: Pozitiv | J6: Yox | K6: Keçdi | L6: EN səhifədən menyu ilə AZ seçildi: /az/kartlar/debet açıldı, mətn tərcümə olundu
A7: UI-LNG-006 | B7: Dil | C7: Dil seçimi yenilədikdən sonra saxlanılır | D7: Brauzer açıqdır | E7: 1. AZ seçin 2. F5 basın | G7: Dil AZ qalır | H7: Yüksək | I7: Pozitiv | J7: Bəli | K7: Keçdi | L7: /en/cards/debet-də F5 sonrası dil EN qalır (dil URL-də saxlanılır) | Avtomatik: language.spec
A8: UI-LNG-007 | B8: Dil | C8: Dil seçimi yeni sessiyada saxlanılır | D8: Brauzer açıqdır | E8: 1. AZ seçin 2. Brauzeri bağlayıb yenidən kök URL açın | G8: Aydın qayda: ya AZ, ya defolt EN. Qayda sənədləşməlidir | H8: Orta | I8: Sərhəd | J8: Yox | K8: İcra olunmayıb | L8: İcra olunmayıb: brauzeri bağlayıb yeni sessiya açmaq bu mühitdə mümkün olmadı
A9: UI-LNG-008 | B9: Dil | C9: Daxili səhifədə dil dəyişəndə eyni səhifədə qalmaq | D9: Brauzer açıqdır | E9: 1. /az/kartlar/debet açın 2. EN seçin | G9: Cari səhifənin EN versiyasına keçir, ana səhifəyə atmır | H9: Yüksək | I9: Neqativ | J9: Yox | K9: Keçdi | L9: /az/kartlar/debet-də EN seçildi: /en/cards/debet açıldı, ana səhifəyə atmadı
A10: UI-LNG-009 | B10: Dil | C10: Brauzer Accept-Language=az olduqda defolt dil | D10: Brauzer açıqdır | E10: 1. Brauzer dilini AZ edin 2. Kök URL açın | G10: Defolt dil qaydası aydındır; EN açılması məhsul qərarı kimi sənədləşməlidir | H10: Orta | I10: Sərhəd | J10: Yox | K10: Keçdi | L10: AZ brauzerdə kök URL /az-a yönləndirir; qayda: brauzer dilinə görə. Selenium-da EN açılır (sənədləşdirilib)
A11: UI-LNG-010 | B11: Dil | C11: Tərcümə tamlığı: AZ səhifədə İngilis/Rus qalıq mətn yoxdur | D11: Brauzer açıqdır | E11: 1. /az açın 2. Bütün bölmə başlıqlarını və düymələri yoxlayın | G11: Tərcüməsiz mətn yoxdur | H11: Orta | I11: Neqativ | J11: Yox | K11: Keçdi | L11: AZ səhifədə bəzi menyu terminləri ingiliscədir (Cash by code, PIN change, 3D secure, FAQ); bank terminləri ola bilər
A12: UI-LNG-011 | B12: Dil | C12: Olmayan dil kodu /xx | D12: Brauzer açıqdır | E12: 1. https://www.bankofbaku.com/xx açın | G12: 404 və ya defolt dilə yönləndirmə, 500 xətası yox | H12: Orta | I12: Neqativ | J12: Yox | K12: İcra olunmayıb | L12: İcra olunmayıb: daxili brauzer yönləndirmə hədəfi bankofbaku.com-u (apex) yükləmir; real Chrome-da yoxlanmalıdır
A13: UI-LNG-012 | B13: Dil | C13: Böyük hərflə dil kodu /AZ | D13: Brauzer açıqdır | E13: 1. https://www.bankofbaku.com/AZ açın | G13: Eyni səhifə və ya düzgün yönləndirmə | H13: Aşağı | I13: Sərhəd | J13: Yox | K13: İcra olunmayıb | L13: İcra olunmayıb: daxili brauzer yönləndirmə hədəfi bankofbaku.com-u (apex) yükləmir; real Chrome-da yoxlanmalıdır
... A26: UI-NAV-012 | B26: Naviqasiya və menyu | C26: Daxili səhifədə F5 yeniləmə | D26: Brauzer açıqdır | E26: 1. /az/kreditler/nagd-pul-krediti açın 2. F5 | G26: Eyni səhifə yüklənir, 404 yox | H26: Yüksək | I26: Neqativ | J26: Bəli | K26: Keçdi | L26: F5 sonrası səhifə eyni qalır, 404 yoxdur (/az/emanetler üzərində yoxlandı) | Avtomatik: navigation.spec
A27: UI-NAV-013 | B27: Naviqasiya və menyu | C27: Menyu klaviatura ilə (Tab, Enter, Esc) | D27: Brauzer açıqdır | E27: 1. Tab ilə menyuda gəzin 2. Enter və Esc | G27: Fokus görünür, alt menyu açılır/bağlanır | H27: Orta | I27: Pozitiv | J27: Yox | K27: İcra olunmayıb
A28: UI-NAV-014 | B28: Naviqasiya və menyu | C28: Menyu elementlərinin səhv yazılışı və uyğunsuz keçidlər | D28: Brauzer açıqdır | E28: 1. Hər keçidin mətnini və hədəfini müqayisə edin | G28: Mətn hədəflə uyğundur | H28: Aşağı | I28: Neqativ | J28: Yox | K28: Keçdi | L28: Menyu mətnləri və href-lər uyğundur (nümunə: Kartlar→/az/kartlar, Əmanətlər→/az/emanetler)
A29: UI-NAV-015 | B29: Naviqasiya və menyu | C29: Menyuda qırıq (404) keçid axtarışı | D29: Brauzer açıqdır | E29: 1. Bütün daxili linklərə sorğu göndərin | G29: Hamısı 200/3xx; 404 yoxdur | H29: Yüksək | I29: Neqativ | J29: Bəli | K29: Keçdi | L29: Avtomatik test (daxili linklər) təsdiqləndi
A30: UI-HOM-001 | B30: Ana səhifə | C30: Ana səhifə bölmələri yüklənir | D30: - | E30: 1. /az açın 2. Aşağı sürüşdürün | G30: Nağd pul krediti, Kartlar, Əmanətlər, Xəbərlər, Filiallar və ATM, Pul köçürmələri bölmələri görünür | H30: Yüksək | I30: Pozitiv | J30: Bəli | K30: Keçdi | L30: Avtomatik test və əl ilə təsdiqləndi
A31: UI-HOM-002 | B31: Ana səhifə | C31: Karusel/banner idarəsi | D31: Brauzer açıqdır | E31: 1. Banner oxlarına və nöqtələrə klik edin | G31: Slaydlar dəyişir, sonuncudan sonra düzgün davranış | H31: Orta | I31: Pozitiv | J31: Yox | K31: İcra olunmayıb
A32: UI-HOM-003 | B32: Ana səhifə | C32: Müraciət et düymələri | D32: Brauzer açıqdır | E32: 1. "Müraciət et" düyməsinə klik edin (forma doldurmadan) | G32: kredit.bankofbaku.com açılır, səhifə yüklənir. Forma göndərilmir | H32: Yüksək | I32: Pozitiv | J32: Yox | K32: Keçdi | L32: Yalnız href yoxlandı (kredit.bankofbaku.com/az/107); düyməyə basılmadı, forma göndərilmədi
A33: UI-HOM-004 | B33: Ana səhifə | C33: Dostbank tətbiq mağazası linkləri | D33: Brauzer açıqdır | E33: 1. AppGallery, Google Play, App Store linklərinə klik | G33: Hər biri düzgün tətbiq səhifəsinə yönləndirir | H33: Orta | I33: Pozitiv | J33: Yox | K33: Keçdi | L33: Google Play, App Store, AppGallery href-ləri mövcuddur (yalnız href yoxlandı)
A34: UI-HOM-005 | B34: Ana səhifə | C34: Ana səhifə konsol xətaları | D34: Brauzer açıqdır | E34: 1. Konsolu açıb /az yükləyin | G34: Kritik JS xətası yoxdur | H34: Orta | I34: Neqativ | J34: Yox | K34: Uğursuz | L34: Konsolda xətalar var: CORS (infobank.az), 404, 400, ERR_TOO_MANY_REDIRECTS (BUG-025)
A35: UI-HOM-006 | B35: Ana səhifə | C35: Şəkillərin yüklənməsi | D35: Brauzer açıqdır | E35: 1. Bütün şəkillərin yükləndiyini yoxlayın | G35: Qırıq şəkil yoxdur, alt mətni var | H35: Orta | I35: Neqativ | J35: Yox | K35: Keçdi | L35: 46 şəkil, qırıq şəkil yoxdur, hamısında alt mətn var
A36: UI-CAL-001 | B36: Kredit kalkulyatoru | C36: Kalkulyator ilkin vəziyyət | D36: Brauzer açıqdır | E36: 1. /az kalkulyator bölməsinə gedin | G36: Neytral defolt növ, sahələr boşdur və ya defolt dəyərlidir | H36: Orta | I36: Pozitiv | J36: Bəli | K36: Uğursuz | L36: BUG-007: özəl növ defolt gəlir
A37: UI-CAL-002 | B37: Kredit kalkulyatoru | C37: Düzgün məbləğ və müddət ilə hesablama | D37: Brauzer açıqdır | E37: 1. Növ seçin 2. Məbləğ 8000, müddət 12 3. Nəticəyə baxın | F37: 8000 / 12 | G37: Aylıq və cəmi ödəniş göstərilir, rəqəm formatı düzgündür | H37: Yüksək | I37: Pozitiv | J37: Bəli | K37: Keçdi | L37: Avtomatik test təsdiqləndi
A38: UI-CAL-003 | B38: Kredit kalkulyatoru | C38: Minimum məbləğ sərhədi (500) | D38: Brauzer açıqdır | E38: 1. Məbləğ 500, müddət 12 | F38: 500 | G38: Hesablanır | H38: Yüksək | I38: Sərhəd | J38: Bəli | K38: Keçdi | L38: Avtomatik test təsdiqləndi
A39: UI-CAL-004 | B39: Kredit kalkulyatoru | C39: Minimumdan aşağı məbləğ (499) | D39: Brauzer açıqdır | E39: 1. Məbləğ 499, müddət 3 | F39: 499 | G39: Xəta mesajı, nəticə göstərilmir | H39: Yüksək | I39: Neqativ | J39: Bəli | K39: Uğursuz | L39: BUG-003
A40: UI-CAL-005 | B40: Kredit kalkulyatoru | C40: Sıfır məbləğ | D40: Brauzer açıqdır | E40: 1. Məbləğ 0 | F40: 0 | G40: Xəta mesajı | H40: Yüksək | I40: Neqativ | J40: Bəli | K40: Uğursuz | L40: BUG-003
A41: UI-CAL-006 | B41: Kredit kalkulyatoru | C41: Mənfi məbləğ | D41: Brauzer açıqdır | E41: 1. Məbləğ -500, müddət 12 | F41: -500 | G41: Mənfi dəyər qəbul edilmir | H41: Yüksək | I41: Neqativ | J41: Yox | K41: Uğursuz | L41: BUG-003
A42: UI-CAL-007 | B42: Kredit kalkulyatoru | C42: Maksimum məbləğ həddi | D42: Brauzer açıqdır | E42: 1. Məbləğ 80000, müddət 59 | F42: 80000 / 59 | G42: Hesablanır | H42: Yüksək | I42: Sərhəd | J42: Yox | K42: Keçdi | L42: 80000 / 59 ay: 2092.05 AZN aylıq, 123430.88 AZN cəmi
A43: UI-CAL-008 | B43: Kredit kalkulyatoru | C43: Maksimumdan yuxarı məbləğ (80001) | D43: Brauzer açıqdır | E43: 1. 80001 yazın | F43: 80001 | G43: Xəta mesajı | H43: Yüksək | I43: Neqativ | J43: Bəli | K43: Uğursuz | L43: BUG-001: sonuncu rəqəm atılır
A44: UI-CAL-009 | B44: Kredit kalkulyatoru | C44: Maksimum müddət (59) | D44: Brauzer açıqdır | E44: 1. Müddət 59 | F44: 59 | G44: Hesablanır | H44: Yüksək | I44: Sərhəd | J44: Yox | K44: Keçdi | L44: Müddət 59 ay hesablanır
A45: UI-CAL-010 | B45: Kredit kalkulyatoru | C45: Maksimumdan yuxarı müddət (60) | D45: Brauzer açıqdır | E45: 1. Müddət 60 yazın | F45: 60 | G45: Xəta mesajı | H45: Yüksək | I45: Neqativ | J45: Bəli | K45: Uğursuz | L45: BUG-002
A46: UI-CAL-011 | B46: Kredit kalkulyatoru | C46: Minimumdan aşağı müddət (2) | D46: Brauzer açıqdır | E46: 1. Müddət 2 | F46: 2 | G46: "Kredit müddəti düzgün qeyd olunmayıb" mesajı | H46: Orta | I46: Neqativ | J46: Yox | K46: Keçdi | L46: Müddət 2: "Kredit müddəti düzgün qeyd olunmayıb" göstərilir
A47: UI-CAL-012 | B47: Kredit kalkulyatoru | C47: Müddət 0 və mənfi | D47: Brauzer açıqdır | E47: 1. Müddət 0, sonra -1 | G47: Xəta mesajı | H47: Orta | I47: Neqativ | J47: Yox | K47: Keçdi | L47: Müddət 0 və -1: eyni xəta mesajı göstərilir
A48: UI-CAL-013 | B48: Kredit kalkulyatoru | C48: Hərf və xüsusi simvol daxil etmək | D48: Brauzer açıqdır | E48: 1. Məbləğə abc, !@#, 1e5 yazın | F48: abc, !@#, 1e5 | G48: Rəqəm olmayan simvollar qəbul edilmir | H48: Yüksək | I48: Neqativ | J48: Yox | K48: Keçdi | L48: Hərflər və !@# qəbul edilmir (sahə 0 olur, nəticə 0.00 AZN, JS xətası yoxdur); 1e5 ayrıca yoxlanmayıb
A49: UI-CAL-014 | B49: Kredit kalkulyatoru | C49: Kəsr məbləğ | D49: Brauzer açıqdır | E49: 1. 1000.55, 1000,55 yazın | G49: Aydın qayda, vergül və nöqtə eyni davranır | H49: Aşağı | I49: Sərhəd | J49: Yox | K49: Uğursuz | L49: BUG-006
A50: UI-CAL-015 | B50: Kredit kalkulyatoru | C50: Boş sahələrlə hesablama | D50: Brauzer açıqdır | E50: 1. Məbləği silin | G50: Nəticə boş və ya təklif mesajı; NaN yoxdur | H50: Orta | I50: Neqativ | J50: Yox | K50: Keçdi | L50: Boş məbləğ: nəticə 0.00 AZN, NaN yoxdur; xəbərdarlıq mesajı yoxdur
A51: UI-CAL-016 | B51: Kredit kalkulyatoru | C51: Cəmi ödəniş = aylıq × müddət | D51: Brauzer açıqdır | E51: 1. 500/3, 1000/12, 10000/36 üçün yoxlayın | G51: Cəmi aylıq × ay ilə uyğundur | H51: Aşağı | I51: Neqativ | J51: Bəli | K51: Uğursuz | L51: BUG-005 | Avtomatik: calculator.spec
A52: UI-CAL-017 | B52: Kredit kalkulyatoru | C52: Növ dəyişəndə nəticə yenilənir | D52: Brauzer açıqdır | E52: 1. Hesablayın 2. Kredit növünü dəyişin | G52: Faiz və nəticə yenilənir | H52: Yüksək | I52: Pozitiv | J52: Bəli | K52: Keçdi | L52: Avtomatik: calculator.spec (Kredit növü dəyişəndə seçim yenilənir)
...

Sheet Avtomatlaşdırma planı
A1: ID | B1: Modul | C1: Başlıq | D1: Prioritet | E1: Üsul | F1: Qeyd
A2: UI-LNG-002 | B2: Dil | C2: Birbaşa /az linki Azərbaycan dilində açılır | D2: Yüksək | E2: Selenium (UI) | F2: Seçim səbəbi: təkrarlanan, sabit lokatorlu və yüksək risklidir
A3: UI-NAV-001 | B3: Naviqasiya və menyu | C3: Əsas menyu elementləri görünür | D3: Yüksək | E3: Selenium (UI) | F3: Seçim səbəbi: təkrarlanan, sabit lokatorlu və yüksək risklidir
A4: UI-NAV-002 | B4: Naviqasiya və menyu | C4: Menyudan keçid: Kartlar | D4: Yüksək | E4: Selenium (UI) | F4: Seçim səbəbi: təkrarlanan, sabit lokatorlu və yüksək risklidir
A5: UI-NAV-010 | B5: Naviqasiya və menyu | C5: Logo ilə ana səhifəyə qayıtmaq | D5: Yüksək | E5: Selenium (UI) | F5: Seçim səbəbi: təkrarlanan, sabit lokatorlu və yüksək risklidir
A6: UI-NAV-015 | B6: Naviqasiya və menyu | C6: Menyuda qırıq (404) keçid axtarışı | D6: Yüksək | E6: HTTP / API yoxlaması | F6: Seçim səbəbi: təkrarlanan, sabit lokatorlu və yüksək risklidir
A7: UI-HOM-001 | B7: Ana səhifə | C7: Ana səhifə bölmələri yüklənir | D7: Yüksək | E7: Selenium (UI) | F7: Seçim səbəbi: təkrarlanan, sabit lokatorlu və yüksək risklidir
A8: UI-CAL-001 | B8: Kredit kalkulyatoru | C8: Kalkulyator ilkin vəziyyət | D8: Orta | E8: Selenium (UI) | F8: Seçim səbəbi: təkrarlanan, sabit lokatorlu və yüksək risklidir
A9: UI-CAL-002 | B9: Kredit kalkulyatoru | C9: Düzgün məbləğ və müddət ilə hesablama | D9: Yüksək | E9: Selenium (UI) | F9: Seçim səbəbi: təkrarlanan, sabit lokatorlu və yüksək risklidir
A10: UI-CAL-003 | B10: Kredit kalkulyatoru | C10: Minimum məbləğ sərhədi (500) | D10: Yüksək | E10: Selenium (UI) | F10: Seçim səbəbi: təkrarlanan, sabit lokatorlu və yüksək risklidir
A11: UI-CAL-004 | B11: Kredit kalkulyatoru | C11: Minimumdan aşağı məbləğ (499) | D11: Yüksək | E11: Selenium (UI) | F11: Seçim səbəbi: təkrarlanan, sabit lokatorlu və yüksək risklidir
A12: UI-CAL-005 | B12: Kredit kalkulyatoru | C12: Sıfır məbləğ | D12: Yüksək | E12: Selenium (UI) | F12: Seçim səbəbi: təkrarlanan, sabit lokatorlu və yüksək risklidir
... A105: UI-NAV-016 | B105: Naviqasiya və menyu | C105: Ana səhifədəki daxili linklər dil prefiksi (/az) daşımalıdır | D105: Orta | E105: Selenium (UI) | F105: Spec ID-si ilə uyğunlaşdırılıb; təkrarlanan, sabit lokatorlu və yüksək risklidir

Sheet İzlənmə matrisi
A1: Modul | B1: Cəmi | C1: Avtomatlaşdırılan | D1: Uğursuz | E1: Yüksək prioritet
A2: Dil | B2: =COUNTIF('Test Case-lər'!B:B,A2) | C2: =COUNTIFS('Test Case-lər'!B:B,A2,'Test Case-lər'!J:J,"Bəli") | D2: =COUNTIFS('Test Case-lər'!B:B,A2,'Test Case-lər'!K:K,"Uğursuz") | E2: =COUNTIFS('Test Case-lər'!B:B,A2,'Test Case-lər'!H:H,"Yüksək")
A3: Naviqasiya və menyu | B3: =COUNTIF('Test Case-lər'!B:B,A3) | C3: =COUNTIFS('Test Case-lər'!B:B,A3,'Test Case-lər'!J:J,"Bəli") | D3: =COUNTIFS('Test Case-lər'!B:B,A3,'Test Case-lər'!K:K,"Uğursuz") | E3: =COUNTIFS('Test Case-lər'!B:B,A3,'Test Case-lər'!H:H,"Yüksək")
A4: Ana səhifə | B4: =COUNTIF('Test Case-lər'!B:B,A4) | C4: =COUNTIFS('Test Case-lər'!B:B,A4,'Test Case-lər'!J:J,"Bəli") | D4: =COUNTIFS('Test Case-lər'!B:B,A4,'Test Case-lər'!K:K,"Uğursuz") | E4: =COUNTIFS('Test Case-lər'!B:B,A4,'Test Case-lər'!H:H,"Yüksək")
A5: Kredit kalkulyatoru | B5: =COUNTIF('Test Case-lər'!B:B,A5) | C5: =COUNTIFS('Test Case-lər'!B:B,A5,'Test Case-lər'!J:J,"Bəli") | D5: =COUNTIFS('Test Case-lər'!B:B,A5,'Test Case-lər'!K:K,"Uğursuz") | E5: =COUNTIFS('Test Case-lər'!B:B,A5,'Test Case-lər'!H:H,"Yüksək")
A6: Kartlar | B6: =COUNTIF('Test Case-lər'!B:B,A6) | C6: =COUNTIFS('Test Case-lər'!B:B,A6,'Test Case-lər'!J:J,"Bəli") | D6: =COUNTIFS('Test Case-lər'!B:B,A6,'Test Case-lər'!K:K,"Uğursuz") | E6: =COUNTIFS('Test Case-lər'!B:B,A6,'Test Case-lər'!H:H,"Yüksək")
A7: Kreditlər | B7: =COUNTIF('Test Case-lər'!B:B,A7) | C7: =COUNTIFS('Test Case-lər'!B:B,A7,'Test Case-lər'!J:J,"Bəli") | D7: =COUNTIFS('Test Case-lər'!B:B,A7,'Test Case-lər'!K:K,"Uğursuz") | E7: =COUNTIFS('Test Case-lər'!B:B,A7,'Test Case-lər'!H:H,"Yüksək")
A8: Əmanətlər | B8: =COUNTIF('Test Case-lər'!B:B,A8) | C8: =COUNTIFS('Test Case-lər'!B:B,A8,'Test Case-lər'!J:J,"Bəli") | D8: =COUNTIFS('Test Case-lər'!B:B,A8,'Test Case-lər'!K:K,"Uğursuz") | E8: =COUNTIFS('Test Case-lər'!B:B,A8,'Test Case-lər'!H:H,"Yüksək")
A9: Pul köçürmələri | B9: =COUNTIF('Test Case-lər'!B:B,A9) | C9: =COUNTIFS('Test Case-lər'!B:B,A9,'Test Case-lər'!J:J,"Bəli") | D9: =COUNTIFS('Test Case-lər'!B:B,A9,'Test Case-lər'!K:K,"Uğursuz") | E9: =COUNTIFS('Test Case-lər'!B:B,A9,'Test Case-lər'!H:H,"Yüksək")
A10: Onlayn xidmətlər | B10: =COUNTIF('Test Case-lər'!B:B,A10) | C10: =COUNTIFS('Test Case-lər'!B:B,A10,'Test Case-lər'!J:J,"Bəli") | D10: =COUNTIFS('Test Case-lər'!B:B,A10,'Test Case-lər'!K:K,"Uğursuz") | E10: =COUNTIFS('Test Case-lər'!B:B,A10,'Test Case-lər'!H:H,"Yüksək")
A11: Digər xidmətlər | B11: =COUNTIF('Test Case-lər'!B:B,A11) | C11: =COUNTIFS('Test Case-lər'!B:B,A11,'Test Case-lər'!J:J,"Bəli") | D11: =COUNTIFS('Test Case-lər'!B:B,A11,'Test Case-lər'!K:K,"Uğursuz") | E11: =COUNTIFS('Test Case-lər'!B:B,A11,'Test Case-lər'!H:H,"Yüksək")
A12: Kampaniyalar | B12: =COUNTIF('Test Case-lər'!B:B,A12) | C12: =COUNTIFS('Test Case-lər'!B:B,A12,'Test Case-lər'!J:J,"Bəli") | D12: =COUNTIFS('Test Case-lər'!B:B,A12,'Test Case-lər'!K:K,"Uğursuz") | E12: =COUNTIFS('Test Case-lər'!B:B,A12,'Test Case-lər'!H:H,"Yüksək")
A13: Biznes | B13: =COUNTIF('Test Case-lər'!B:B,A13) | C13: =COUNTIFS('Test Case-lər'!B:B,A13,'Test Case-lər'!J:J,"Bəli") | D13: =COUNTIFS('Test Case-lər'!B:B,A13,'Test Case-lər'!K:K,"Uğursuz") | E13: =COUNTIFS('Test Case-lər'!B:B,A13,'Test Case-lər'!H:H,"Yüksək")
... A25: Çat və əlavə widget-lər | B25: =COUNTIF('Test Case-lər'!B:B,A25) | C25: =COUNTIFS('Test Case-lər'!B:B,A25,'Test Case-lər'!J:J,"Bəli") | D25: =COUNTIFS('Test Case-lər'!B:B,A25,'Test Case-lər'!K:K,"Uğursuz") | E25: =COUNTIFS('Test Case-lər'!B:B,A25,'Test Case-lər'!H:H,"Yüksək")
A26: Cəmi | B26: =SUM(B2:B25) | C26: =SUM(C2:C25) | D26: =SUM(D2:D25) | E26: =SUM(E2:E25)

Sheet Müşahidələr və Risklər
A1: № | B1: Tip | C1: Təsvir | D1: Təsir | E1: Tövsiyə
A2: 1 | B2: Risk | C2: Sayt kök URL-də həmişə İngilis dilində açılır | D2: Azərbaycanlı istifadəçi üçün çaşqınlıq; testlərdə yanlış dil | E2: Avtomatlaşdırmada həmişə /az ilə başlamaq, dil qaydasını biznesdən dəqiqləşdirmək
A3: 2 | B3: Risk | C3: Angular SPA: dinamik yüklənmə | D3: Sabit olmayan lokatorlar, flaky testlər | E3: Explicit wait, data-* atributları və ya sabit CSS lokatorları
A4: 3 | B4: Risk | C4: Çat və əlavə widget-lər elementləri örtə bilər | D4: Klik xətaları | E4: Testdə widget-i bağlamaq və ya JS click
A5: 4 | B5: Məhdudiyyət | C5: Giriş (e-bankofbaku.com) və formaların göndərilməsi test edilmir | D5: Bu hissələr əhatədən kənardır | E5: Yalnız validasiya və keçid yoxlanır
A6: 5 | B6: Müşahidə | C6: Kalkulyatorda 7 bug (BUG-001…007) | D6: Yanlış hesablama riski | E6: Ayrıca "Bug siyahısı" faylına baxın
A7: 6 | B7: Müşahidə | C7: Valyuta cədvəlində GBP və RUB spredi geniş | D7: Bug yox, yoxlanmalıdır | E7: Biznes ilə dəqiqləşdirmək
A8: 7 | B8: Qeyd | C8: Statuslar: 278 case-dən 155-i əl ilə yoxlanıldı (5 Bloklanıb); 14 case (hücum xarakterli, performans, kontrast və s.) icra olunmayıb | D8: - | E8: İcradan sonra yenilənir
A9: 8 | B9: Müşahidə | C9: Nağd GBP və RUB məzənnə fərqi (spred) geniş: GBP 2.0000/2.2800, RUB 1.2000/2.0100 | D9: Bug yox, bank qərarı ola bilər | E9: Biznes ilə dəqiqləşdirmək
A10: 9 | B10: Müşahidə | C10: Konvertor xarici valyutadan AZN-ə çevirmədə Satış məzənnəsini istifadə edir (100 USD → 170.00 AZN) | D10: Maliyyə məlumatıdır | E10: Biznesdən təsdiq almaq
A11: 10 | B11: Müşahidə | C11: Kart və kredit detal ünvanları ardıcıl deyil (rəqəm və slug qarışıqdır, /kartlar və /kreditler) | D11: Funksional problem yoxdur; SEO və saxlanılabilirlik | E11: Ünvan qaydasını standartlaşdırmaq
A12: 11 | B12: Risk | C12: İlk açılışda izləmə kukiləri razılıq soruşulmadan qurulur (_ga, _fbp, _ym_uid və s.) | D12: Qanunvericiliyə uyğunluq riski | E12: Hüquq şöbəsi qiymətləndirməlidir
A13: 12 | B13: Risk | C13: CSP başlığı məhduddur, Permissions-Policy yoxdur | D13: Təhlükəsizlik möhkəmləndirməsi | E13: Təhlükəsizlik komandasına ötürmək
... A18: 17 | B18: Müşahidə | C18: Daxili səhifələrdə canonical linki həmişə /az ana səhifəsinə işarə edir | D18: SEO | E18: Canonical-ı səhifənin öz ünvanına yönəltmək
